[2025-07-12T06:21:26.973+0000] {local_task_job_runner.py:120} INFO - ::group::Pre task execution logs
[2025-07-12T06:21:26.996+0000] {taskinstance.py:2076} INFO - Dependencies all met for dep_context=non-requeueable deps ti=<TaskInstance: initialize_historical_data.initialize_historical_data manual__2025-07-11T16:36:56.028978+00:00 [queued]>
[2025-07-12T06:21:27.003+0000] {taskinstance.py:2076} INFO - Dependencies all met for dep_context=requeueable deps ti=<TaskInstance: initialize_historical_data.initialize_historical_data manual__2025-07-11T16:36:56.028978+00:00 [queued]>
[2025-07-12T06:21:27.003+0000] {taskinstance.py:2306} INFO - Starting attempt 1 of 2
[2025-07-12T06:21:27.014+0000] {taskinstance.py:2330} INFO - Executing <Task(BashOperator): initialize_historical_data> on 2025-07-11 16:36:56.028978+00:00
[2025-07-12T06:21:27.023+0000] {standard_task_runner.py:90} INFO - Running: ['***', 'tasks', 'run', 'initialize_historical_data', 'initialize_historical_data', 'manual__2025-07-11T16:36:56.028978+00:00', '--job-id', '17', '--raw', '--subdir', 'DAGS_FOLDER/initialize_historical_data.py', '--cfg-path', '/tmp/tmpsxb76aam']
[2025-07-12T06:21:27.025+0000] {standard_task_runner.py:91} INFO - Job 17: Subtask initialize_historical_data
[2025-07-12T06:21:27.027+0000] {logging_mixin.py:188} WARNING - /home/***/.local/lib/python3.12/site-packages/***/task/task_runner/standard_task_runner.py:61 DeprecationWarning: This process (pid=300) is multi-threaded, use of fork() may lead to deadlocks in the child.
[2025-07-12T06:21:27.027+0000] {standard_task_runner.py:63} INFO - Started process 302 to run task
[2025-07-12T06:21:27.065+0000] {task_command.py:426} INFO - Running <TaskInstance: initialize_historical_data.initialize_historical_data manual__2025-07-11T16:36:56.028978+00:00 [running]> on host 397e8f811de3
[2025-07-12T06:21:27.135+0000] {taskinstance.py:2648} INFO - Exporting env vars: AIRFLOW_CTX_DAG_OWNER='***' AIRFLOW_CTX_DAG_ID='initialize_historical_data' AIRFLOW_CTX_TASK_ID='initialize_historical_data' AIRFLOW_CTX_EXECUTION_DATE='2025-07-11T16:36:56.028978+00:00' AIRFLOW_CTX_TRY_NUMBER='1' AIRFLOW_CTX_DAG_RUN_ID='manual__2025-07-11T16:36:56.028978+00:00'
[2025-07-12T06:21:27.136+0000] {taskinstance.py:430} INFO - ::endgroup::
[2025-07-12T06:21:27.147+0000] {subprocess.py:63} INFO - Tmp dir root location: /tmp
[2025-07-12T06:21:27.148+0000] {subprocess.py:75} INFO - Running command: ['/usr/bin/bash', '-c', 'docker exec -i crypto_data_collector python3 /app/data/initialize_historical_data.py']
[2025-07-12T06:21:27.159+0000] {subprocess.py:86} INFO - Output:
[2025-07-12T06:21:27.212+0000] {subprocess.py:93} INFO - python3: can't open file '/app/data/initialize_historical_data.py': [Errno 2] No such file or directory
[2025-07-12T06:21:27.216+0000] {subprocess.py:97} INFO - Command exited with return code 2
[2025-07-12T06:21:27.217+0000] {taskinstance.py:441} INFO - ::group::Post task execution logs
[2025-07-12T06:21:27.229+0000] {taskinstance.py:2905} ERROR - Task failed with exception
Traceback (most recent call last):
  File "/home/airflow/.local/lib/python3.12/site-packages/airflow/models/taskinstance.py", line 465, in _execute_task
    result = _execute_callable(context=context, **execute_callable_kwargs)
             ^^^^^^^^^^^^^^^^^^^^^^^^^^^^^^^^^^^^^^^^^^^^^^^^^^^^^^^^^^^^^
  File "/home/airflow/.local/lib/python3.12/site-packages/airflow/models/taskinstance.py", line 432, in _execute_callable
    return execute_callable(context=context, **execute_callable_kwargs)
           ^^^^^^^^^^^^^^^^^^^^^^^^^^^^^^^^^^^^^^^^^^^^^^^^^^^^^^^^^^^^
  File "/home/airflow/.local/lib/python3.12/site-packages/airflow/models/baseoperator.py", line 400, in wrapper
    return func(self, *args, **kwargs)
           ^^^^^^^^^^^^^^^^^^^^^^^^^^^
  File "/home/airflow/.local/lib/python3.12/site-packages/airflow/operators/bash.py", line 243, in execute
    raise AirflowException(
airflow.exceptions.AirflowException: Bash command failed. The command returned a non-zero exit code 2.
[2025-07-12T06:21:27.233+0000] {taskinstance.py:1206} INFO - Marking task as UP_FOR_RETRY. dag_id=initialize_historical_data, task_id=initialize_historical_data, run_id=manual__2025-07-11T16:36:56.028978+00:00, execution_date=20250711T163656, start_date=20250712T062126, end_date=20250712T062127
[2025-07-12T06:21:27.243+0000] {standard_task_runner.py:110} ERROR - Failed to execute job 17 for task initialize_historical_data (Bash command failed. The command returned a non-zero exit code 2.; 302)
[2025-07-12T06:21:27.281+0000] {local_task_job_runner.py:240} INFO - Task exited with return code 1
[2025-07-12T06:21:27.300+0000] {taskinstance.py:3498} INFO - 0 downstream tasks scheduled from follow-on schedule check
[2025-07-12T06:21:27.302+0000] {local_task_job_runner.py:222} INFO - ::endgroup::
