[2025-07-12T06:15:11.314+0000] {local_task_job_runner.py:120} INFO - ::group::Pre task execution logs
[2025-07-12T06:15:11.338+0000] {taskinstance.py:2076} INFO - Dependencies all met for dep_context=non-requeueable deps ti=<TaskInstance: update_historical_data.update_historical_data manual__2025-07-12T06:15:10.859371+00:00 [queued]>
[2025-07-12T06:15:11.343+0000] {taskinstance.py:2076} INFO - Dependencies all met for dep_context=requeueable deps ti=<TaskInstance: update_historical_data.update_historical_data manual__2025-07-12T06:15:10.859371+00:00 [queued]>
[2025-07-12T06:15:11.343+0000] {taskinstance.py:2306} INFO - Starting attempt 1 of 2
[2025-07-12T06:15:11.351+0000] {taskinstance.py:2330} INFO - Executing <Task(BashOperator): update_historical_data> on 2025-07-12 06:15:10.859371+00:00
[2025-07-12T06:15:11.357+0000] {standard_task_runner.py:90} INFO - Running: ['***', 'tasks', 'run', 'update_historical_data', 'update_historical_data', 'manual__2025-07-12T06:15:10.859371+00:00', '--job-id', '13', '--raw', '--subdir', 'DAGS_FOLDER/update_historical_data.py', '--cfg-path', '/tmp/tmpuix5ku8a']
[2025-07-12T06:15:11.359+0000] {standard_task_runner.py:91} INFO - Job 13: Subtask update_historical_data
[2025-07-12T06:15:11.359+0000] {logging_mixin.py:188} WARNING - /home/***/.local/lib/python3.12/site-packages/***/task/task_runner/standard_task_runner.py:61 DeprecationWarning: This process (pid=236) is multi-threaded, use of fork() may lead to deadlocks in the child.
[2025-07-12T06:15:11.360+0000] {standard_task_runner.py:63} INFO - Started process 237 to run task
[2025-07-12T06:15:11.392+0000] {task_command.py:426} INFO - Running <TaskInstance: update_historical_data.update_historical_data manual__2025-07-12T06:15:10.859371+00:00 [running]> on host 185a615a5471
[2025-07-12T06:15:11.458+0000] {taskinstance.py:2648} INFO - Exporting env vars: AIRFLOW_CTX_DAG_OWNER='***' AIRFLOW_CTX_DAG_ID='update_historical_data' AIRFLOW_CTX_TASK_ID='update_historical_data' AIRFLOW_CTX_EXECUTION_DATE='2025-07-12T06:15:10.859371+00:00' AIRFLOW_CTX_TRY_NUMBER='1' AIRFLOW_CTX_DAG_RUN_ID='manual__2025-07-12T06:15:10.859371+00:00'
[2025-07-12T06:15:11.458+0000] {taskinstance.py:430} INFO - ::endgroup::
[2025-07-12T06:15:11.470+0000] {subprocess.py:63} INFO - Tmp dir root location: /tmp
[2025-07-12T06:15:11.470+0000] {subprocess.py:75} INFO - Running command: ['/usr/bin/bash', '-c', 'docker ps']
[2025-07-12T06:15:11.480+0000] {subprocess.py:86} INFO - Output:
[2025-07-12T06:15:11.491+0000] {subprocess.py:93} INFO - permission denied while trying to connect to the Docker daemon socket at unix:///var/run/docker.sock: Get "http://%2Fvar%2Frun%2Fdocker.sock/v1.45/containers/json": dial unix /var/run/docker.sock: connect: permission denied
[2025-07-12T06:15:11.492+0000] {subprocess.py:97} INFO - Command exited with return code 1
[2025-07-12T06:15:11.493+0000] {taskinstance.py:441} INFO - ::group::Post task execution logs
[2025-07-12T06:15:11.502+0000] {taskinstance.py:2905} ERROR - Task failed with exception
Traceback (most recent call last):
  File "/home/airflow/.local/lib/python3.12/site-packages/airflow/models/taskinstance.py", line 465, in _execute_task
    result = _execute_callable(context=context, **execute_callable_kwargs)
             ^^^^^^^^^^^^^^^^^^^^^^^^^^^^^^^^^^^^^^^^^^^^^^^^^^^^^^^^^^^^^
  File "/home/airflow/.local/lib/python3.12/site-packages/airflow/models/taskinstance.py", line 432, in _execute_callable
    return execute_callable(context=context, **execute_callable_kwargs)
           ^^^^^^^^^^^^^^^^^^^^^^^^^^^^^^^^^^^^^^^^^^^^^^^^^^^^^^^^^^^^
  File "/home/airflow/.local/lib/python3.12/site-packages/airflow/models/baseoperator.py", line 400, in wrapper
    return func(self, *args, **kwargs)
           ^^^^^^^^^^^^^^^^^^^^^^^^^^^
  File "/home/airflow/.local/lib/python3.12/site-packages/airflow/operators/bash.py", line 243, in execute
    raise AirflowException(
airflow.exceptions.AirflowException: Bash command failed. The command returned a non-zero exit code 1.
[2025-07-12T06:15:11.505+0000] {taskinstance.py:1206} INFO - Marking task as UP_FOR_RETRY. dag_id=update_historical_data, task_id=update_historical_data, run_id=manual__2025-07-12T06:15:10.859371+00:00, execution_date=20250712T061510, start_date=20250712T061511, end_date=20250712T061511
[2025-07-12T06:15:11.513+0000] {standard_task_runner.py:110} ERROR - Failed to execute job 13 for task update_historical_data (Bash command failed. The command returned a non-zero exit code 1.; 237)
[2025-07-12T06:15:11.532+0000] {local_task_job_runner.py:240} INFO - Task exited with return code 1
[2025-07-12T06:15:11.546+0000] {taskinstance.py:3498} INFO - 0 downstream tasks scheduled from follow-on schedule check
[2025-07-12T06:15:11.547+0000] {local_task_job_runner.py:222} INFO - ::endgroup::
