[2025-07-12T06:12:39.696+0000] {local_task_job_runner.py:120} INFO - ::group::Pre task execution logs
[2025-07-12T06:12:39.719+0000] {taskinstance.py:2076} INFO - Dependencies all met for dep_context=non-requeueable deps ti=<TaskInstance: update_historical_data.update_historical_data manual__2025-07-12T06:02:54.356341+00:00 [queued]>
[2025-07-12T06:12:39.724+0000] {taskinstance.py:2076} INFO - Dependencies all met for dep_context=requeueable deps ti=<TaskInstance: update_historical_data.update_historical_data manual__2025-07-12T06:02:54.356341+00:00 [queued]>
[2025-07-12T06:12:39.724+0000] {taskinstance.py:2306} INFO - Starting attempt 1 of 2
[2025-07-12T06:12:39.731+0000] {taskinstance.py:2330} INFO - Executing <Task(BashOperator): update_historical_data> on 2025-07-12 06:02:54.356341+00:00
[2025-07-12T06:12:39.736+0000] {standard_task_runner.py:90} INFO - Running: ['***', 'tasks', 'run', 'update_historical_data', 'update_historical_data', 'manual__2025-07-12T06:02:54.356341+00:00', '--job-id', '12', '--raw', '--subdir', 'DAGS_FOLDER/update_historical_data.py', '--cfg-path', '/tmp/tmpotvw4pgg']
[2025-07-12T06:12:39.738+0000] {standard_task_runner.py:91} INFO - Job 12: Subtask update_historical_data
[2025-07-12T06:12:39.738+0000] {logging_mixin.py:188} WARNING - /home/***/.local/lib/python3.12/site-packages/***/task/task_runner/standard_task_runner.py:61 DeprecationWarning: This process (pid=170) is multi-threaded, use of fork() may lead to deadlocks in the child.
[2025-07-12T06:12:39.738+0000] {standard_task_runner.py:63} INFO - Started process 171 to run task
[2025-07-12T06:12:39.771+0000] {task_command.py:426} INFO - Running <TaskInstance: update_historical_data.update_historical_data manual__2025-07-12T06:02:54.356341+00:00 [running]> on host 185a615a5471
[2025-07-12T06:12:39.843+0000] {taskinstance.py:2648} INFO - Exporting env vars: AIRFLOW_CTX_DAG_OWNER='***' AIRFLOW_CTX_DAG_ID='update_historical_data' AIRFLOW_CTX_TASK_ID='update_historical_data' AIRFLOW_CTX_EXECUTION_DATE='2025-07-12T06:02:54.356341+00:00' AIRFLOW_CTX_TRY_NUMBER='1' AIRFLOW_CTX_DAG_RUN_ID='manual__2025-07-12T06:02:54.356341+00:00'
[2025-07-12T06:12:39.843+0000] {taskinstance.py:430} INFO - ::endgroup::
[2025-07-12T06:12:39.865+0000] {subprocess.py:63} INFO - Tmp dir root location: /tmp
[2025-07-12T06:12:39.866+0000] {subprocess.py:75} INFO - Running command: ['/usr/bin/bash', '-c', 'docker ps']
[2025-07-12T06:12:39.872+0000] {subprocess.py:86} INFO - Output:
[2025-07-12T06:12:39.881+0000] {subprocess.py:93} INFO - permission denied while trying to connect to the Docker daemon socket at unix:///var/run/docker.sock: Get "http://%2Fvar%2Frun%2Fdocker.sock/v1.45/containers/json": dial unix /var/run/docker.sock: connect: permission denied
[2025-07-12T06:12:39.882+0000] {subprocess.py:97} INFO - Command exited with return code 1
[2025-07-12T06:12:39.882+0000] {taskinstance.py:441} INFO - ::group::Post task execution logs
[2025-07-12T06:12:39.890+0000] {taskinstance.py:2905} ERROR - Task failed with exception
Traceback (most recent call last):
  File "/home/airflow/.local/lib/python3.12/site-packages/airflow/models/taskinstance.py", line 465, in _execute_task
    result = _execute_callable(context=context, **execute_callable_kwargs)
             ^^^^^^^^^^^^^^^^^^^^^^^^^^^^^^^^^^^^^^^^^^^^^^^^^^^^^^^^^^^^^
  File "/home/airflow/.local/lib/python3.12/site-packages/airflow/models/taskinstance.py", line 432, in _execute_callable
    return execute_callable(context=context, **execute_callable_kwargs)
           ^^^^^^^^^^^^^^^^^^^^^^^^^^^^^^^^^^^^^^^^^^^^^^^^^^^^^^^^^^^^
  File "/home/airflow/.local/lib/python3.12/site-packages/airflow/models/baseoperator.py", line 400, in wrapper
    return func(self, *args, **kwargs)
           ^^^^^^^^^^^^^^^^^^^^^^^^^^^
  File "/home/airflow/.local/lib/python3.12/site-packages/airflow/operators/bash.py", line 243, in execute
    raise AirflowException(
airflow.exceptions.AirflowException: Bash command failed. The command returned a non-zero exit code 1.
[2025-07-12T06:12:39.893+0000] {taskinstance.py:1206} INFO - Marking task as UP_FOR_RETRY. dag_id=update_historical_data, task_id=update_historical_data, run_id=manual__2025-07-12T06:02:54.356341+00:00, execution_date=20250712T060254, start_date=20250712T061239, end_date=20250712T061239
[2025-07-12T06:12:39.900+0000] {standard_task_runner.py:110} ERROR - Failed to execute job 12 for task update_historical_data (Bash command failed. The command returned a non-zero exit code 1.; 171)
[2025-07-12T06:12:39.911+0000] {local_task_job_runner.py:240} INFO - Task exited with return code 1
[2025-07-12T06:12:39.924+0000] {taskinstance.py:3498} INFO - 0 downstream tasks scheduled from follow-on schedule check
[2025-07-12T06:12:39.925+0000] {local_task_job_runner.py:222} INFO - ::endgroup::
